Workbook
Name ScrollableTable: OFFSET('Pivot Table'!$A$214:$H$249, 'Pivot Table'!A1048562:F1048571, 0, 12, 7)
Name Slicer_fiscal_year: #N/A
Name Slicer_fiscal_year1: #N/A
Name Slicer_fiscal_year3: #N/A
Name Slicer_Months__date: #N/A
Name Slicer_vehicle_category: #N/A
Name Slicer_vehicle_category1: #N/A
Name Slicer_vehicle_category2: #N/A
Name Slicer_vehicle_category3: #N/A

Sheet dim_date
A1: date | B1: fiscal_year | C1: quarter
A2: 44287 | B2: 2022 | C2: Q1
A3: 44317 | B3: 2022 | C3: Q1
A4: 44348 | B4: 2022 | C4: Q1
A5: 44378 | B5: 2022 | C5: Q2
A6: 44409 | B6: 2022 | C6: Q2
A7: 44440 | B7: 2022 | C7: Q2
A8: 44470 | B8: 2022 | C8: Q3
A9: 44501 | B9: 2022 | C9: Q3
A10: 44531 | B10: 2022 | C10: Q3
A11: 44562 | B11: 2022 | C11: Q4
A12: 44593 | B12: 2022 | C12: Q4
A13: 44621 | B13: 2022 | C13: Q4
... A37: 45352 | B37: 2024 | C37: Q4

Sheet electric_vehicle_sales_by_maker
A1: date | B1: fiscal_year | C1: vehicle_category | D1: maker | E1: electric_vehicles_sold
A2: 44287 | B2: =VLOOKUP(electric_vehicle_sales_by_makers[[#This Row],[date]], dim_date!A:C, 2, FALSE) -> 2022 | C2: 2-Wheelers | D2: AMPERE | E2: 751
A3: 44652 | B3: =VLOOKUP(electric_vehicle_sales_by_makers[[#This Row],[date]], dim_date!A:C, 2, FALSE) -> 2023 | C3: 2-Wheelers | D3: AMPERE | E3: 6864
A4: 45017 | B4: =VLOOKUP(electric_vehicle_sales_by_makers[[#This Row],[date]], dim_date!A:C, 2, FALSE) -> 2024 | C4: 2-Wheelers | D4: AMPERE | E4: 8767
A5: 44317 | B5: =VLOOKUP(electric_vehicle_sales_by_makers[[#This Row],[date]], dim_date!A:C, 2, FALSE) -> 2022 | C5: 2-Wheelers | D5: AMPERE | E5: 147
A6: 44682 | B6: =VLOOKUP(electric_vehicle_sales_by_makers[[#This Row],[date]], dim_date!A:C, 2, FALSE) -> 2023 | C6: 2-Wheelers | D6: AMPERE | E6: 6176
A7: 45047 | B7: =VLOOKUP(electric_vehicle_sales_by_makers[[#This Row],[date]], dim_date!A:C, 2, FALSE) -> 2024 | C7: 2-Wheelers | D7: AMPERE | E7: 10659
A8: 44348 | B8: =VLOOKUP(electric_vehicle_sales_by_makers[[#This Row],[date]], dim_date!A:C, 2, FALSE) -> 2022 | C8: 2-Wheelers | D8: AMPERE | E8: 299
A9: 44713 | B9: =VLOOKUP(electric_vehicle_sales_by_makers[[#This Row],[date]], dim_date!A:C, 2, FALSE) -> 2023 | C9: 2-Wheelers | D9: AMPERE | E9: 6919
A10: 45078 | B10: =VLOOKUP(electric_vehicle_sales_by_makers[[#This Row],[date]], dim_date!A:C, 2, FALSE) -> 2024 | C10: 2-Wheelers | D10: AMPERE | E10: 3006
A11: 44378 | B11: =VLOOKUP(electric_vehicle_sales_by_makers[[#This Row],[date]], dim_date!A:C, 2, FALSE) -> 2022 | C11: 2-Wheelers | D11: AMPERE | E11: 663
A12: 44743 | B12: =VLOOKUP(electric_vehicle_sales_by_makers[[#This Row],[date]], dim_date!A:C, 2, FALSE) -> 2023 | C12: 2-Wheelers | D12: AMPERE | E12: 6812
A13: 45108 | B13: =VLOOKUP(electric_vehicle_sales_by_makers[[#This Row],[date]], dim_date!A:C, 2, FALSE) -> 2024 | C13: 2-Wheelers | D13: AMPERE | E13: 3530
... A817: 45352 | B817: =VLOOKUP(electric_vehicle_sales_by_makers[[#This Row],[date]], dim_date!A:C, 2, FALSE) -> 2024 | C817: 4-Wheelers | D817: Volvo Auto India | E817: 39

Sheet electric_vehicle_sales_by_state
A1: date | B1: fiscal_year | C1: state | D1: vehicle_category | E1: electric_vehicles_sold | F1: total_vehicles_sold | G1: Avg_Price | H1: Revenue
A2: 44287 | B2: =VLOOKUP(electric_vehicle_sales_by_state[[#This Row],[date]], dim_date[#All],2, FALSE) -> 2022 | C2: Sikkim | D2: 2-Wheelers | E2: 0 | F2: 398 | G2: =IF(electric_vehicle_sales_by_state[[#This Row],[vehicle_category]]="2-Wheelers",85000,1500000) -> 85000 | H2: =(electric_vehicle_sales_by_state[[#This Row],[electric_vehicles_sold]]*electric_vehicle_sales_by_state[[#This Row],[Avg_Price]]) -> 0
A3: 44317 | B3: =VLOOKUP(electric_vehicle_sales_by_state[[#This Row],[date]], dim_date[#All],2, FALSE) -> 2022 | C3: Sikkim | D3: 2-Wheelers | E3: 0 | F3: 113 | G3: =IF(electric_vehicle_sales_by_state[[#This Row],[vehicle_category]]="2-Wheelers",85000,1500000) -> 85000 | H3: =(electric_vehicle_sales_by_state[[#This Row],[electric_vehicles_sold]]*electric_vehicle_sales_by_state[[#This Row],[Avg_Price]]) -> 0
A4: 44348 | B4: =VLOOKUP(electric_vehicle_sales_by_state[[#This Row],[date]], dim_date[#All],2, FALSE) -> 2022 | C4: Sikkim | D4: 2-Wheelers | E4: 0 | F4: 229 | G4: =IF(electric_vehicle_sales_by_state[[#This Row],[vehicle_category]]="2-Wheelers",85000,1500000) -> 85000 | H4: =(electric_vehicle_sales_by_state[[#This Row],[electric_vehicles_sold]]*electric_vehicle_sales_by_state[[#This Row],[Avg_Price]]) -> 0
A5: 44378 | B5: =VLOOKUP(electric_vehicle_sales_by_state[[#This Row],[date]], dim_date[#All],2, FALSE) -> 2022 | C5: Sikkim | D5: 2-Wheelers | E5: 0 | F5: 458 | G5: =IF(electric_vehicle_sales_by_state[[#This Row],[vehicle_category]]="2-Wheelers",85000,1500000) -> 85000 | H5: =(electric_vehicle_sales_by_state[[#This Row],[electric_vehicles_sold]]*electric_vehicle_sales_by_state[[#This Row],[Avg_Price]]) -> 0
A6: 44409 | B6: =VLOOKUP(electric_vehicle_sales_by_state[[#This Row],[date]], dim_date[#All],2, FALSE) -> 2022 | C6: Sikkim | D6: 2-Wheelers | E6: 0 | F6: 489 | G6: =IF(electric_vehicle_sales_by_state[[#This Row],[vehicle_category]]="2-Wheelers",85000,1500000) -> 85000 | H6: =(electric_vehicle_sales_by_state[[#This Row],[electric_vehicles_sold]]*electric_vehicle_sales_by_state[[#This Row],[Avg_Price]]) -> 0
A7: 44440 | B7: =VLOOKUP(electric_vehicle_sales_by_state[[#This Row],[date]], dim_date[#All],2, FALSE) -> 2022 | C7: Sikkim | D7: 2-Wheelers | E7: 0 | F7: 540 | G7: =IF(electric_vehicle_sales_by_state[[#This Row],[vehicle_category]]="2-Wheelers",85000,1500000) -> 85000 | H7: =(electric_vehicle_sales_by_state[[#This Row],[electric_vehicles_sold]]*electric_vehicle_sales_by_state[[#This Row],[Avg_Price]]) -> 0
A8: 44470 | B8: =VLOOKUP(electric_vehicle_sales_by_state[[#This Row],[date]], dim_date[#All],2, FALSE) -> 2022 | C8: Sikkim | D8: 2-Wheelers | E8: 0 | F8: 455 | G8: =IF(electric_vehicle_sales_by_state[[#This Row],[vehicle_category]]="2-Wheelers",85000,1500000) -> 85000 | H8: =(electric_vehicle_sales_by_state[[#This Row],[electric_vehicles_sold]]*electric_vehicle_sales_by_state[[#This Row],[Avg_Price]]) -> 0
A9: 44501 | B9: =VLOOKUP(electric_vehicle_sales_by_state[[#This Row],[date]], dim_date[#All],2, FALSE) -> 2022 | C9: Sikkim | D9: 2-Wheelers | E9: 0 | F9: 478 | G9: =IF(electric_vehicle_sales_by_state[[#This Row],[vehicle_category]]="2-Wheelers",85000,1500000) -> 85000 | H9: =(electric_vehicle_sales_by_state[[#This Row],[electric_vehicles_sold]]*electric_vehicle_sales_by_state[[#This Row],[Avg_Price]]) -> 0
A10: 44531 | B10: =VLOOKUP(electric_vehicle_sales_by_state[[#This Row],[date]], dim_date[#All],2, FALSE) -> 2022 | C10: Sikkim | D10: 2-Wheelers | E10: 0 | F10: 454 | G10: =IF(electric_vehicle_sales_by_state[[#This Row],[vehicle_category]]="2-Wheelers",85000,1500000) -> 85000 | H10: =(electric_vehicle_sales_by_state[[#This Row],[electric_vehicles_sold]]*electric_vehicle_sales_by_state[[#This Row],[Avg_Price]]) -> 0
A11: 44562 | B11: =VLOOKUP(electric_vehicle_sales_by_state[[#This Row],[date]], dim_date[#All],2, FALSE) -> 2022 | C11: Sikkim | D11: 2-Wheelers | E11: 0 | F11: 400 | G11: =IF(electric_vehicle_sales_by_state[[#This Row],[vehicle_category]]="2-Wheelers",85000,1500000) -> 85000 | H11: =(electric_vehicle_sales_by_state[[#This Row],[electric_vehicles_sold]]*electric_vehicle_sales_by_state[[#This Row],[Avg_Price]]) -> 0
A12: 44593 | B12: =VLOOKUP(electric_vehicle_sales_by_state[[#This Row],[date]], dim_date[#All],2, FALSE) -> 2022 | C12: Sikkim | D12: 2-Wheelers | E12: 0 | F12: 384 | G12: =IF(electric_vehicle_sales_by_state[[#This Row],[vehicle_category]]="2-Wheelers",85000,1500000) -> 85000 | H12: =(electric_vehicle_sales_by_state[[#This Row],[electric_vehicles_sold]]*electric_vehicle_sales_by_state[[#This Row],[Avg_Price]]) -> 0
A13: 44621 | B13: =VLOOKUP(electric_vehicle_sales_by_state[[#This Row],[date]], dim_date[#All],2, FALSE) -> 2022 | C13: Sikkim | D13: 2-Wheelers | E13: 0 | F13: 460 | G13: =IF(electric_vehicle_sales_by_state[[#This Row],[vehicle_category]]="2-Wheelers",85000,1500000) -> 85000 | H13: =(electric_vehicle_sales_by_state[[#This Row],[electric_vehicles_sold]]*electric_vehicle_sales_by_state[[#This Row],[Avg_Price]]) -> 0
... A2446: 45352 | B2446: =VLOOKUP(electric_vehicle_sales_by_state[[#This Row],[date]], dim_date[#All],2, FALSE) -> 2024 | C2446: Manipur | D2446: 4-Wheelers | E2446: 2 | F2446: 370 | G2446: =IF(electric_vehicle_sales_by_state[[#This Row],[vehicle_category]]="2-Wheelers",85000,1500000) -> 1500000 | H2446: =(electric_vehicle_sales_by_state[[#This Row],[electric_vehicles_sold]]*electric_vehicle_sales_by_state[[#This Row],[Avg_Price]]) -> 3000000

Sheet PRC
A1: Penetration_Rate | B1: 2022 | D1: 2023 | F1: 2024 | H1: Penetration_Rate_Year_wise | K1: Penetration_Change | N1: Penetration_Rate According to vehicals & Category wise
A2: State | B2: Total_EV_Sales | C2: Total_vehicles_sold | D2: Total_EV_Sales2 | E2: Total_vehicles_sold3 | F2: Total_EV_Sales4 | G2: Total_vehicles_sold5 | H2: PR_2022 | I2: PR_2023 | J2: PR_2024 | K2: PRC_2022-2023 | L2: PRC_2023-2024 | M2: PRC_2022-2024 | N2: PR_2-wheeler_2022 | O2: PR_4-wheeler_2022 | P2: PR_2-wheeler_2023 | Q2: PR_4-wheeler_2023 | R2: PR_2-wheeler_2024 | S2: PR_4-wheeler_2024
A3: Sikkim | B3: =SUMIFS(electric_vehicle_sales_by_state[electric_vehicles_sold],electric_vehicle_sales_by_state[state], A3,electric_vehicle_sales_by_state[fiscal_year],2022) -> 0 | C3: =SUMIFS(electric_vehicle_sales_by_state[total_vehicles_sold],electric_vehicle_sales_by_state[state], A3,electric_vehicle_sales_by_state[fiscal_year],2022) -> 8897 | D3: =SUMIFS(electric_vehicle_sales_by_state[electric_vehicles_sold],electric_vehicle_sales_by_state[state], A3,electric_vehicle_sales_by_state[fiscal_year],2023) -> 0 | E3: =SUMIFS(electric_vehicle_sales_by_state[total_vehicles_sold],electric_vehicle_sales_by_state[state], A3,electric_vehicle_sales_by_state[fiscal_year],2023) -> 9931 | F3: =SUMIFS(electric_vehicle_sales_by_state[electric_vehicles_sold],electric_vehicle_sales_by_state[state], A3,electric_vehicle_sales_by_state[fiscal_year],2024) -> 0 | G3: =SUMIFS(electric_vehicle_sales_by_state[total_vehicles_sold],electric_vehicle_sales_by_state[state], A3,electric_vehicle_sales_by_state[fiscal_year],2024) -> 10518 | H3: =IFERROR((B3/C3), 0) -> 0 | I3: =IFERROR((D3/E3), 0) -> 0 | J3: =IFERROR((F3/G3), 0) -> 0 | K3: =IFERROR((I3-H3),0) -> 0 | L3: =IFERROR((J3-I3),0) -> 0 | M3: =IFERROR((Table8[[#This Row],[PR_2024]]-Table8[[#This Row],[PR_2022]]),0) -> 0 | N3: =IFERROR( SUMIFS( electric_vehicle_sales_by_state[electric_vehicles_sold], electric_vehicle_sales_by_state[state], A3, electric_vehicle_sales_by_state[vehicle_category], "2-Wheelers", electric_vehicle_sales_by_state[fiscal_year], 2022 ) / SUMIFS( electric_vehicle_sales_by_state[total_vehicles_sold], electric_vehicle_sales_by_state[state], A3, electric_vehicle_sales_by_state[vehicle_category], "2-Wheelers", electric_vehicle_sales_by_state[fiscal_year], 2022 ), 0) -> 0 | O3: =IFERROR( SUMIFS( electric_vehicle_sales_by_state[electric_vehicles_sold], electric_vehicle_sales_by_state[state], A3, electric_vehicle_sales_by_state[vehicle_category], "4-Wheelers", electric_vehicle_sales_by_state[fiscal_year], 2022 ) / SUMIFS( electric_vehicle_sales_by_state[total_vehicles_sold], electric_vehicle_sales_by_state[state], A3, electric_vehicle_sales_by_state[vehicle_category], "4-Wheelers", electric_vehicle_sales_by_state[fiscal_year], 2022 ), 0) -> 0 | P3: =IFERROR( SUMIFS( electric_vehicle_sales_by_state[electric_vehicles_sold], electric_vehicle_sales_by_state[state], A3, electric_vehicle_sales_by_state[vehicle_category], "2-Wheelers", electric_vehicle_sales_by_state[fiscal_year], 2023 ) / SUMIFS( electric_vehicle_sales_by_state[total_vehicles_sold], electric_vehicle_sales_by_state[state], A3, electric_vehicle_sales_by_state[vehicle_category], "2-Wheelers", electric_vehicle_sales_by_state[fiscal_year], 2023 ), 0) -> 0 | Q3: =IFERROR( SUMIFS( electric_vehicle_sales_by_state[electric_vehicles_sold], electric_vehicle_sales_by_state[state], A3, electric_vehicle_sales_by_state[vehicle_category], "4-Wheelers", electric_vehicle_sales_by_state[fiscal_year], 2023 ) / SUMIFS( electric_vehicle_sales_by_state[total_vehicles_sold], electric_vehicle_sales_by_state[state], A3, electric_vehicle_sales_by_state[vehicle_category], "4-Wheelers", electric_vehicle_sales_by_state[fiscal_year], 2023 ), 0) -> 0 | R3: =IFERROR( SUMIFS( electric_vehicle_sales_by_state[electric_vehicles_sold], electric_vehicle_sales_by_state[state], A3, electric_vehicle_sales_by_state[vehicle_category], "2-Wheelers", electric_vehicle_sales_by_state[fiscal_year], 2024 ) / SUMIFS( electric_vehicle_sales_by_state[total_vehicles_sold], electric_vehicle_sales_by_state[state], A3, electric_vehicle_sales_by_state[vehicle_category], "2-Wheelers", electric_vehicle_sales_by_state[fiscal_year], 2024 ), 0) -> 0 | S3: =IFERROR( SUMIFS( electric_vehicle_sales_by_state[electric_vehicles_sold], electric_vehicle_sales_by_state[state], A3, electric_vehicle_sales_by_state[vehicle_category], "4-Wheelers", electric_vehicle_sales_by_state[fiscal_year], 2024 ) / SUMIFS( electric_vehicle_sales_by_state[total_vehicles_sold], electric_vehicle_sales_by_state[state], A3, electric_vehicle_sales_by_state[vehicle_category], "4-Wheelers", electric_vehicle_sales_by_state[fiscal_year], 2024 ), 0) -> 0
A4: Andaman & Nicobar Island | B4: =SUMIFS(electric_vehicle_sales_by_state[electric_vehicles_sold],electric_vehicle_sales_by_state[state], A4,electric_vehicle_sales_by_state[fiscal_year],2022) -> 22 | C4: =SUMIFS(electric_vehicle_sales_by_state[total_vehicles_sold],electric_vehicle_sales_by_state[state], A4,electric_vehicle_sales_by_state[fiscal_year],2022) -> 5148 | D4: =SUMIFS(electric_vehicle_sales_by_state[electric_vehicles_sold],electric_vehicle_sales_by_state[state], A4,electric_vehicle_sales_by_state[fiscal_year],2023) -> 23 | E4: =SUMIFS(electric_vehicle_sales_by_state[total_vehicles_sold],electric_vehicle_sales_by_state[state], A4,electric_vehicle_sales_by_state[fiscal_year],2023) -> 6534 | F4: =SUMIFS(electric_vehicle_sales_by_state[electric_vehicles_sold],electric_vehicle_sales_by_state[state], A4,electric_vehicle_sales_by_state[fiscal_year],2024) -> 33 | G4: =SUMIFS(electric_vehicle_sales_by_state[total_vehicles_sold],electric_vehicle_sales_by_state[state], A4,electric_vehicle_sales_by_state[fiscal_year],2024) -> 6543 | H4: =IFERROR((B4/C4), 0) -> 0.0042735043 | I4: =IFERROR((D4/E4), 0) -> 0.003520049 | J4: =IFERROR((F4/G4), 0) -> 0.005043558 | K4: =IFERROR((I4-H4),0) -> -0.0007534553 | L4: =IFERROR((J4-I4),0) -> 0.001523509 | M4: =IFERROR((Table8[[#This Row],[PR_2024]]-Table8[[#This Row],[PR_2022]]),0) -> 0.00077005373 | N4: =IFERROR( SUMIFS( electric_vehicle_sales_by_state[electric_vehicles_sold], electric_vehicle_sales_by_state[state], A4, electric_vehicle_sales_by_state[vehicle_category], "2-Wheelers", electric_vehicle_sales_by_state[fiscal_year], 2022 ) / SUMIFS( electric_vehicle_sales_by_state[total_vehicles_sold], electric_vehicle_sales_by_state[state], A4, electric_vehicle_sales_by_state[vehicle_category], "2-Wheelers", electric_vehicle_sales_by_state[fiscal_year], 2022 ), 0) -> 0 | O4: =IFERROR( SUMIFS( electric_vehicle_sales_by_state[electric_vehicles_sold], electric_vehicle_sales_by_state[state], A4, electric_vehicle_sales_by_state[vehicle_category], "4-Wheelers", electric_vehicle_sales_by_state[fiscal_year], 2022 ) / SUMIFS( electric_vehicle_sales_by_state[total_vehicles_sold], electric_vehicle_sales_by_state[state], A4, electric_vehicle_sales_by_state[vehicle_category], "4-Wheelers", electric_vehicle_sales_by_state[fiscal_year], 2022 ), 0) -> 0.018819504 | P4: =IFERROR( SUMIFS( electric_vehicle_sales_by_state[electric_vehicles_sold], electric_vehicle_sales_by_state[state], A4, electric_vehicle_sales_by_state[vehicle_category], "2-Wheelers", electric_vehicle_sales_by_state[fiscal_year], 2023 ) / SUMIFS( electric_vehicle_sales_by_state[total_vehicles_sold], electric_vehicle_sales_by_state[state], A4, electric_vehicle_sales_by_state[vehicle_category], "2-Wheelers", electric_vehicle_sales_by_state[fiscal_year], 2023 ), 0) -> 0.0035729298 | Q4: =IFERROR( SUMIFS( electric_vehicle_sales_by_state[electric_vehicles_sold], electric_vehicle_sales_by_state[state], A4, electric_vehicle_sales_by_state[vehicle_category], "4-Wheelers", electric_vehicle_sales_by_state[fiscal_year], 2023 ) / SUMIFS( electric_vehicle_sales_by_state[total_vehicles_sold], electric_vehicle_sales_by_state[state], A4, electric_vehicle_sales_by_state[vehicle_category], "4-Wheelers", electric_vehicle_sales_by_state[fiscal_year], 2023 ), 0) -> 0.0033783784 | R4: =IFERROR( SUMIFS( electric_vehicle_sales_by_state[electric_vehicles_sold], electric_vehicle_sales_by_state[state], A4, electric_vehicle_sales_by_state[vehicle_category], "2-Wheelers", electric_vehicle_sales_by_state[fiscal_year], 2024 ) / SUMIFS( electric_vehicle_sales_by_state[total_vehicles_sold], electric_vehicle_sales_by_state[state], A4, electric_vehicle_sales_by_state[vehicle_category], "2-Wheelers", electric_vehicle_sales_by_state[fiscal_year], 2024 ), 0) -> 0.003776752 | S4: =IFERROR( SUMIFS( electric_vehicle_sales_by_state[electric_vehicles_sold], electric_vehicle_sales_by_state[state], A4, electric_vehicle_sales_by_state[vehicle_category], "4-Wheelers", electric_vehicle_sales_by_state[fiscal_year], 2024 ) / SUMIFS( electric_vehicle_sales_by_state[total_vehicles_sold], electric_vehicle_sales_by_state[state], A4, electric_vehicle_sales_by_state[vehicle_category], "4-Wheelers", electric_vehicle_sales_by_state[fiscal_year], 2024 ), 0) -> 0.008441193
A5: Arunachal Pradesh | B5: =SUMIFS(electric_vehicle_sales_by_state[electric_vehicles_sold],electric_vehicle_sales_by_state[state], A5,electric_vehicle_sales_by_state[fiscal_year],2022) -> 0 | C5: =SUMIFS(electric_vehicle_sales_by_state[total_vehicles_sold],electric_vehicle_sales_by_state[state], A5,electric_vehicle_sales_by_state[fiscal_year],2022) -> 19929 | D5: =SUMIFS(electric_vehicle_sales_by_state[electric_vehicles_sold],electric_vehicle_sales_by_state[state], A5,electric_vehicle_sales_by_state[fiscal_year],2023) -> 2 | E5: =SUMIFS(electric_vehicle_sales_by_state[total_vehicles_sold],electric_vehicle_sales_by_state[state], A5,electric_vehicle_sales_by_state[fiscal_year],2023) -> 23726 | F5: =SUMIFS(electric_vehicle_sales_by_state[electric_vehicles_sold],electric_vehicle_sales_by_state[state], A5,electric_vehicle_sales_by_state[fiscal_year],2024) -> 31 | G5: =SUMIFS(electric_vehicle_sales_by_state[total_vehicles_sold],electric_vehicle_sales_by_state[state], A5,electric_vehicle_sales_by_state[fiscal_year],2024) -> 27892 | H5: =IFERROR((B5/C5), 0) -> 0 | I5: =IFERROR((D5/E5), 0) -> 8.4295709e-05 | J5: =IFERROR((F5/G5), 0) -> 0.0011114298 | K5: =IFERROR((I5-H5),0) -> 8.4295709e-05 | L5: =IFERROR((J5-I5),0) -> 0.0010271341 | M5: =IFERROR((Table8[[#This Row],[PR_2024]]-Table8[[#This Row],[PR_2022]]),0) -> 0.0011114298 | N5: =IFERROR( SUMIFS( electric_vehicle_sales_by_state[electric_vehicles_sold], electric_vehicle_sales_by_state[state], A5, electric_vehicle_sales_by_state[vehicle_category], "2-Wheelers", electric_vehicle_sales_by_state[fiscal_year], 2022 ) / SUMIFS( electric_vehicle_sales_by_state[total_vehicles_sold], electric_vehicle_sales_by_state[state], A5, electric_vehicle_sales_by_state[vehicle_category], "2-Wheelers", electric_vehicle_sales_by_state[fiscal_year], 2022 ), 0) -> 0 | O5: =IFERROR( SUMIFS( electric_vehicle_sales_by_state[electric_vehicles_sold], electric_vehicle_sales_by_state[state], A5, electric_vehicle_sales_by_state[vehicle_category], "4-Wheelers", electric_vehicle_sales_by_state[fiscal_year], 2022 ) / SUMIFS( electric_vehicle_sales_by_state[total_vehicles_sold], electric_vehicle_sales_by_state[state], A5, electric_vehicle_sales_by_state[vehicle_category], "4-Wheelers", electric_vehicle_sales_by_state[fiscal_year], 2022 ), 0) -> 0 | P5: =IFERROR( SUMIFS( electric_vehicle_sales_by_state[electric_vehicles_sold], electric_vehicle_sales_by_state[state], A5, electric_vehicle_sales_by_state[vehicle_category], "2-Wheelers", electric_vehicle_sales_by_state[fiscal_year], 2023 ) / SUMIFS( electric_vehicle_sales_by_state[total_vehicles_sold], electric_vehicle_sales_by_state[state], A5, electric_vehicle_sales_by_state[vehicle_category], "2-Wheelers", electric_vehicle_sales_by_state[fiscal_year], 2023 ), 0) -> 7.8486775e-05 | Q5: =IFERROR( SUMIFS( electric_vehicle_sales_by_state[electric_vehicles_sold], electric_vehicle_sales_by_state[state], A5, electric_vehicle_sales_by_state[vehicle_category], "4-Wheelers", electric_vehicle_sales_by_state[fiscal_year], 2023 ) / SUMIFS( electric_vehicle_sales_by_state[total_vehicles_sold], electric_vehicle_sales_by_state[state], A5, electric_vehicle_sales_by_state[vehicle_category], "4-Wheelers", electric_vehicle_sales_by_state[fiscal_year], 2023 ), 0) -> 9.1033227e-05 | R5: =IFERROR( SUMIFS( electric_vehicle_sales_by_state[electric_vehicles_sold], electric_vehicle_sales_by_state[state], A5, electric_vehicle_sales_by_state[vehicle_category], "2-Wheelers", electric_vehicle_sales_by_state[fiscal_year], 2024 ) / SUMIFS( electric_vehicle_sales_by_state[total_vehicles_sold], electric_vehicle_sales_by_state[state], A5, electric_vehicle_sales_by_state[vehicle_category], "2-Wheelers", electric_vehicle_sales_by_state[fiscal_year], 2024 ), 0) -> 0.00020445717 | S5: =IFERROR( SUMIFS( electric_vehicle_sales_by_state[electric_vehicles_sold], electric_vehicle_sales_by_state[state], A5, electric_vehicle_sales_by_state[vehicle_category], "4-Wheelers", electric_vehicle_sales_by_state[fiscal_year], 2024 ) / SUMIFS( electric_vehicle_sales_by_state[total_vehicles_sold], electric_vehicle_sales_by_state[state], A5, electric_vehicle_sales_by_state[vehicle_category], "4-Wheelers", electric_vehicle_sales_by_state[fiscal_year], 2024 ), 0) -> 0.0021181632
A6: Assam | B6: =SUMIFS(electric_vehicle_sales_by_state[electric_vehicles_sold],electric_vehicle_sales_by_state[state], A6,electric_vehicle_sales_by_state[fiscal_year],2022) -> 730 | C6: =SUMIFS(electric_vehicle_sales_by_state[total_vehicles_sold],electric_vehicle_sales_by_state[state], A6,electric_vehicle_sales_by_state[fiscal_year],2022) -> 379450 | D6: =SUMIFS(electric_vehicle_sales_by_state[electric_vehicles_sold],electric_vehicle_sales_by_state[state], A6,electric_vehicle_sales_by_state[fiscal_year],2023) -> 2191 | E6: =SUMIFS(electric_vehicle_sales_by_state[total_vehicles_sold],electric_vehicle_sales_by_state[state], A6,electric_vehicle_sales_by_state[fiscal_year],2023) -> 476195 | F6: =SUMIFS(electric_vehicle_sales_by_state[electric_vehicles_sold],electric_vehicle_sales_by_state[state], A6,electric_vehicle_sales_by_state[fiscal_year],2024) -> 3497 | G6: =SUMIFS(electric_vehicle_sales_by_state[total_vehicles_sold],electric_vehicle_sales_by_state[state], A6,electric_vehicle_sales_by_state[fiscal_year],2024) -> 547626 | H6: =IFERROR((B6/C6), 0) -> 0.0019238371 | I6: =IFERROR((D6/E6), 0) -> 0.0046010563 | J6: =IFERROR((F6/G6), 0) -> 0.006385745 | K6: =IFERROR((I6-H6),0) -> 0.0026772192 | L6: =IFERROR((J6-I6),0) -> 0.0017846887 | M6: =IFERROR((Table8[[#This Row],[PR_2024]]-Table8[[#This Row],[PR_2022]]),0) -> 0.0044619079 | N6: =IFERROR( SUMIFS( electric_vehicle_sales_by_state[electric_vehicles_sold], electric_vehicle_sales_by_state[state], A6, electric_vehicle_sales_by_state[vehicle_category], "2-Wheelers", electric_vehicle_sales_by_state[fiscal_year], 2022 ) / SUMIFS( electric_vehicle_sales_by_state[total_vehicles_sold], electric_vehicle_sales_by_state[state], A6, electric_vehicle_sales_by_state[vehicle_category], "2-Wheelers", electric_vehicle_sales_by_state[fiscal_year], 2022 ), 0) -> 0.002311518 | O6: =IFERROR( SUMIFS( electric_vehicle_sales_by_state[electric_vehicles_sold], electric_vehicle_sales_by_state[state], A6, electric_vehicle_sales_by_state[vehicle_category], "4-Wheelers", electric_vehicle_sales_by_state[fiscal_year], 2022 ) / SUMIFS( electric_vehicle_sales_by_state[total_vehicles_sold], electric_vehicle_sales_by_state[state], A6, electric_vehicle_sales_by_state[vehicle_category], "4-Wheelers", electric_vehicle_sales_by_state[fiscal_year], 2022 ), 0) -> 0.00016082106 | P6: =IFERROR( SUMIFS( electric_vehicle_sales_by_state[electric_vehicles_sold], electric_vehicle_sales_by_state[state], A6, electric_vehicle_sales_by_state[vehicle_category], "2-Wheelers", electric_vehicle_sales_by_state[fiscal_year], 2023 ) / SUMIFS( electric_vehicle_sales_by_state[total_vehicles_sold], electric_vehicle_sales_by_state[state], A6, electric_vehicle_sales_by_state[vehicle_category], "2-Wheelers", electric_vehicle_sales_by_state[fiscal_year], 2023 ), 0) -> 0.0053391766 | Q6: =IFERROR( SUMIFS( electric_vehicle_sales_by_state[electric_vehicles_sold], electric_vehicle_sales_by_state[state], A6, electric_vehicle_sales_by_state[vehicle_category], "4-Wheelers", electric_vehicle_sales_by_state[fiscal_year], 2023 ) / SUMIFS( electric_vehicle_sales_by_state[total_vehicles_sold], electric_vehicle_sales_by_state[state], A6, electric_vehicle_sales_by_state[vehicle_category], "4-Wheelers", electric_vehicle_sales_by_state[fiscal_year], 2023 ), 0) -> 0.0013162262 | R6: =IFERROR( SUMIFS( electric_vehicle_sales_by_state[electric_vehicles_sold], electric_vehicle_sales_by_state[state], A6, electric_vehicle_sales_by_state[vehicle_category], "2-Wheelers", electric_vehicle_sales_by_state[fiscal_year], 2024 ) / SUMIFS( electric_vehicle_sales_by_state[total_vehicles_sold], electric_vehicle_sales_by_state[state], A6, electric_vehicle_sales_by_state[vehicle_category], "2-Wheelers", electric_vehicle_sales_by_state[fiscal_year], 2024 ), 0) -> 0.0069363251 | S6: =IFERROR( SUMIFS( electric_vehicle_sales_by_state[electric_vehicles_sold], electric_vehicle_sales_by_state[state], A6, electric_vehicle_sales_by_state[vehicle_category], "4-Wheelers", electric_vehicle_sales_by_state[fiscal_year], 2024 ) / SUMIFS( electric_vehicle_sales_by_state[total_vehicles_sold], electric_vehicle_sales_by_state[state], A6, electric_vehicle_sales_by_state[vehicle_category], "4-Wheelers", electric_vehicle_sales_by_state[fiscal_year], 2024 ), 0) -> 0.0036193619
A7: Chhattisgarh | B7: =SUMIFS(electric_vehicle_sales_by_state[electric_vehicles_sold],electric_vehicle_sales_by_state[state], A7,electric_vehicle_sales_by_state[fiscal_year],2022) -> 4534 | C7: =SUMIFS(electric_vehicle_sales_by_state[total_vehicles_sold],electric_vehicle_sales_by_state[state], A7,electric_vehicle_sales_by_state[fiscal_year],2022) -> 390272 | D7: =SUMIFS(electric_vehicle_sales_by_state[electric_vehicles_sold],electric_vehicle_sales_by_state[state], A7,electric_vehicle_sales_by_state[fiscal_year],2023) -> 20730 | E7: =SUMIFS(electric_vehicle_sales_by_state[total_vehicles_sold],electric_vehicle_sales_by_state[state], A7,electric_vehicle_sales_by_state[fiscal_year],2023) -> 441649 | F7: =SUMIFS(electric_vehicle_sales_by_state[electric_vehicles_sold],electric_vehicle_sales_by_state[state], A7,electric_vehicle_sales_by_state[fiscal_year],2024) -> 28540 | G7: =SUMIFS(electric_vehicle_sales_by_state[total_vehicles_sold],electric_vehicle_sales_by_state[state], A7,electric_vehicle_sales_by_state[fiscal_year],2024) -> 503068 | H7: =IFERROR((B7/C7), 0) -> 0.011617539 | I7: =IFERROR((D7/E7), 0) -> 0.046937727 | J7: =IFERROR((F7/G7), 0) -> 0.056731893 | K7: =IFERROR((I7-H7),0) -> 0.035320188 | L7: =IFERROR((J7-I7),0) -> 0.0097941665 | M7: =IFERROR((Table8[[#This Row],[PR_2024]]-Table8[[#This Row],[PR_2022]]),0) -> 0.045114355 | N7: =IFERROR( SUMIFS( electric_vehicle_sales_by_state[electric_vehicles_sold], electric_vehicle_sales_by_state[state], A7, electric_vehicle_sales_by_state[vehicle_category], "2-Wheelers", electric_vehicle_sales_by_state[fiscal_year], 2022 ) / SUMIFS( electric_vehicle_sales_by_state[total_vehicles_sold], electric_vehicle_sales_by_state[state], A7, electric_vehicle_sales_by_state[vehicle_category], "2-Wheelers", electric_vehicle_sales_by_state[fiscal_year], 2022 ), 0) -> 0.012855275 | O7: =IFERROR( SUMIFS( electric_vehicle_sales_by_state[electric_vehicles_sold], electric_vehicle_sales_by_state[state], A7, electric_vehicle_sales_by_state[vehicle_category], "4-Wheelers", electric_vehicle_sales_by_state[fiscal_year], 2022 ) / SUMIFS( electric_vehicle_sales_by_state[total_vehicles_sold], electric_vehicle_sales_by_state[state], A7, electric_vehicle_sales_by_state[vehicle_category], "4-Wheelers", electric_vehicle_sales_by_state[fiscal_year], 2022 ), 0) -> 0.0025580354 | P7: =IFERROR( SUMIFS( electric_vehicle_sales_by_state[electric_vehicles_sold], electric_vehicle_sales_by_state[state], A7, electric_vehicle_sales_by_state[vehicle_category], "2-Wheelers", electric_vehicle_sales_by_state[fiscal_year], 2023 ) / SUMIFS( electric_vehicle_sales_by_state[total_vehicles_sold], electric_vehicle_sales_by_state[state], A7, electric_vehicle_sales_by_state[vehicle_category], "2-Wheelers", electric_vehicle_sales_by_state[fiscal_year], 2023 ), 0) -> 0.052200125 | Q7: =IFERROR( SUMIFS( electric_vehicle_sales_by_state[electric_vehicles_sold], electric_vehicle_sales_by_state[state], A7, electric_vehicle_sales_by_state[vehicle_category], "4-Wheelers", electric_vehicle_sales_by_state[fiscal_year], 2023 ) / SUMIFS( electric_vehicle_sales_by_state[total_vehicles_sold], electric_vehicle_sales_by_state[state], A7, electric_vehicle_sales_by_state[vehicle_category], "4-Wheelers", electric_vehicle_sales_by_state[fiscal_year], 2023 ), 0) -> 0.0098121466 | R7: =IFERROR( SUMIFS( electric_vehicle_sales_by_state[electric_vehicles_sold], electric_vehicle_sales_by_state[state], A7, electric_vehicle_sales_by_state[vehicle_category], "2-Wheelers", electric_vehicle_sales_by_state[fiscal_year], 2024 ) / SUMIFS( electric_vehicle_sales_by_state[total_vehicles_sold], electric_vehicle_sales_by_state[state], A7, electric_vehicle_sales_by_state[vehicle_category], "2-Wheelers", electric_vehicle_sales_by_state[fiscal_year], 2024 ), 0) -> 0.060482923 | S7: =IFERROR( SUMIFS( electric_vehicle_sales_by_state[electric_vehicles_sold], electric_vehicle_sales_by_state[state], A7, electric_vehicle_sales_by_state[vehicle_category], "4-Wheelers", electric_vehicle_sales_by_state[fiscal_year], 2024 ) / SUMIFS( electric_vehicle_sales_by_state[total_vehicles_sold], electric_vehicle_sales_by_state[state], A7, electric_vehicle_sales_by_state[vehicle_category], "4-Wheelers", electric_vehicle_sales_by_state[fiscal_year], 2024 ), 0) -> 0.024181447
A8: DNH and DD | B8: =SUMIFS(electric_vehicle_sales_by_state[electric_vehicles_sold],electric_vehicle_sales_by_state[state], A8,electric_vehicle_sales_by_state[fiscal_year],2022) -> 35 | C8: =SUMIFS(electric_vehicle_sales_by_state[total_vehicles_sold],electric_vehicle_sales_by_state[state], A8,electric_vehicle_sales_by_state[fiscal_year],2022) -> 12413 | D8: =SUMIFS(electric_vehicle_sales_by_state[electric_vehicles_sold],electric_vehicle_sales_by_state[state], A8,electric_vehicle_sales_by_state[fiscal_year],2023) -> 122 | E8: =SUMIFS(electric_vehicle_sales_by_state[total_vehicles_sold],electric_vehicle_sales_by_state[state], A8,electric_vehicle_sales_by_state[fiscal_year],2023) -> 14584 | F8: =SUMIFS(electric_vehicle_sales_by_state[electric_vehicles_sold],electric_vehicle_sales_by_state[state], A8,electric_vehicle_sales_by_state[fiscal_year],2024) -> 198 | G8: =SUMIFS(electric_vehicle_sales_by_state[total_vehicles_sold],electric_vehicle_sales_by_state[state], A8,electric_vehicle_sales_by_state[fiscal_year],2024) -> 16400 | H8: =IFERROR((B8/C8), 0) -> 0.0028196246 | I8: =IFERROR((D8/E8), 0) -> 0.0083653319 | J8: =IFERROR((F8/G8), 0) -> 0.012073171 | K8: =IFERROR((I8-H8),0) -> 0.0055457073 | L8: =IFERROR((J8-I8),0) -> 0.0037078389 | M8: =IFERROR((Table8[[#This Row],[PR_2024]]-Table8[[#This Row],[PR_2022]]),0) -> 0.0092535461 | N8: =IFERROR( SUMIFS( electric_vehicle_sales_by_state[electric_vehicles_sold], electric_vehicle_sales_by_state[state], A8, electric_vehicle_sales_by_state[vehicle_category], "2-Wheelers", electric_vehicle_sales_by_state[fiscal_year], 2022 ) / SUMIFS( electric_vehicle_sales_by_state[total_vehicles_sold], electric_vehicle_sales_by_state[state], A8, electric_vehicle_sales_by_state[vehicle_category], "2-Wheelers", electric_vehicle_sales_by_state[fiscal_year], 2022 ), 0) -> 0.0034530387 | O8: =IFERROR( SUMIFS( electric_vehicle_sales_by_state[electric_vehicles_sold], electric_vehicle_sales_by_state[state], A8, electric_vehicle_sales_by_state[vehicle_category], "4-Wheelers", electric_vehicle_sales_by_state[fiscal_year], 2022 ) / SUMIFS( electric_vehicle_sales_by_state[total_vehicles_sold], electric_vehicle_sales_by_state[state], A8, electric_vehicle_sales_by_state[vehicle_category], "4-Wheelers", electric_vehicle_sales_by_state[fiscal_year], 2022 ), 0) -> 0.0013422819 | P8: =IFERROR( SUMIFS( electric_vehicle_sales_by_state[electric_vehicles_sold], electric_vehicle_sales_by_state[state], A8, electric_vehicle_sales_by_state[vehicle_category], "2-Wheelers", electric_vehicle_sales_by_state[fiscal_year], 2023 ) / SUMIFS( electric_vehicle_sales_by_state[total_vehicles_sold], electric_vehicle_sales_by_state[state], A8, electric_vehicle_sales_by_state[vehicle_category], "2-Wheelers", electric_vehicle_sales_by_state[fiscal_year], 2023 ), 0) -> 0.010339584 | Q8: =IFERROR( SUMIFS( electric_vehicle_sales_by_state[electric_vehicles_sold], electric_vehicle_sales_by_state[state], A8, electric_vehicle_sales_by_state[vehicle_category], "4-Wheelers", electric_vehicle_sales_by_state[fiscal_year], 2023 ) / SUMIFS( electric_vehicle_sales_by_state[total_vehicles_sold], electric_vehicle_sales_by_state[state], A8, electric_vehicle_sales_by_state[vehicle_category], "4-Wheelers", electric_vehicle_sales_by_state[fiscal_year], 2023 ), 0) -> 0.0042381861 | R8: =IFERROR( SUMIFS( electric_vehicle_sales_by_state[electric_vehicles_sold], electric_vehicle_sales_by_state[state], A8, electric_vehicle_sales_by_state[vehicle_category], "2-Wheelers", electric_vehicle_sales_by_state[fiscal_year], 2024 ) / SUMIFS( electric_vehicle_sales_by_state[total_vehicles_sold], electric_vehicle_sales_by_state[state], A8, electric_vehicle_sales_by_state[vehicle_category], "2-Wheelers", electric_vehicle_sales_by_state[fiscal_year], 2024 ), 0) -> 0.013678509 | S8: =IFERROR( SUMIFS( electric_vehicle_sales_by_state[electric_vehicles_sold], electric_vehicle_sales_by_state[state], A8, electric_vehicle_sales_by_state[vehicle_category], "4-Wheelers", electric_vehicle_sales_by_state[fiscal_year], 2024 ) / SUMIFS( electric_vehicle_sales_by_state[total_vehicles_sold], electric_vehicle_sales_by_state[state], A8, electric_vehicle_sales_by_state[vehicle_category], "4-Wheelers", electric_vehicle_sales_by_state[fiscal_year], 2024 ), 0) -> 0.0088977665
A9: Jammu and Kashmir | B9: =SUMIFS(electric_vehicle_sales_by_state[electric_vehicles_sold],electric_vehicle_sales_by_state[state], A9,electric_vehicle_sales_by_state[fiscal_year],2022) -> 1434 | C9: =SUMIFS(electric_vehicle_sales_by_state[total_vehicles_sold],electric_vehicle_sales_by_state[state], A9,electric_vehicle_sales_by_state[fiscal_year],2022) -> 133943 | D9: =SUMIFS(electric_vehicle_sales_by_state[electric_vehicles_sold],electric_vehicle_sales_by_state[state], A9,electric_vehicle_sales_by_state[fiscal_year],2023) -> 2254 | E9: =SUMIFS(electric_vehicle_sales_by_state[total_vehicles_sold],electric_vehicle_sales_by_state[state], A9,electric_vehicle_sales_by_state[fiscal_year],2023) -> 141251 | F9: =SUMIFS(electric_vehicle_sales_by_state[electric_vehicles_sold],electric_vehicle_sales_by_state[state], A9,electric_vehicle_sales_by_state[fiscal_year],2024) -> 2283 | G9: =SUMIFS(electric_vehicle_sales_by_state[total_vehicles_sold],electric_vehicle_sales_by_state[state], A9,electric_vehicle_sales_by_state[fiscal_year],2024) -> 139359 | H9: =IFERROR((B9/C9), 0) -> 0.010706047 | I9: =IFERROR((D9/E9), 0) -> 0.015957409 | J9: =IFERROR((F9/G9), 0) -> 0.01638215 | K9: =IFERROR((I9-H9),0) -> 0.0052513625 | L9: =IFERROR((J9-I9),0) -> 0.00042474055 | M9: =IFERROR((Table8[[#This Row],[PR_2024]]-Table8[[#This Row],[PR_2022]]),0) -> 0.0056761031 | N9: =IFERROR( SUMIFS( electric_vehicle_sales_by_state[electric_vehicles_sold], electric_vehicle_sales_by_state[state], A9, electric_vehicle_sales_by_state[vehicle_category], "2-Wheelers", electric_vehicle_sales_by_state[fiscal_year], 2022 ) / SUMIFS( electric_vehicle_sales_by_state[total_vehicles_sold], electric_vehicle_sales_by_state[state], A9, electric_vehicle_sales_by_state[vehicle_category], "2-Wheelers", electric_vehicle_sales_by_state[fiscal_year], 2022 ), 0) -> 0.017782794 | O9: =IFERROR( SUMIFS( electric_vehicle_sales_by_state[electric_vehicles_sold], electric_vehicle_sales_by_state[state], A9, electric_vehicle_sales_by_state[vehicle_category], "4-Wheelers", electric_vehicle_sales_by_state[fiscal_year], 2022 ) / SUMIFS( electric_vehicle_sales_by_state[total_vehicles_sold], electric_vehicle_sales_by_state[state], A9, electric_vehicle_sales_by_state[vehicle_category], "4-Wheelers", electric_vehicle_sales_by_state[fiscal_year], 2022 ), 0) -> 0.00029518661 | P9: =IFERROR( SUMIFS( electric_vehicle_sales_by_state[electric_vehicles_sold], electric_vehicle_sales_by_state[state], A9, electric_vehicle_sales_by_state[vehicle_category], "2-Wheelers", electric_vehicle_sales_by_state[fiscal_year], 2023 ) / SUMIFS( electric_vehicle_sales_by_state[total_vehicles_sold], electric_vehicle_sales_by_state[state], A9, electric_vehicle_sales_by_state[vehicle_category], "2-Wheelers", electric_vehicle_sales_by_state[fiscal_year], 2023 ), 0) -> 0.025319092 | Q9: =IFERROR( SUMIFS( electric_vehicle_sales_by_state[electric_vehicles_sold], electric_vehicle_sales_by_state[state], A9, electric_vehicle_sales_by_state[vehicle_category], "4-Wheelers", electric_vehicle_sales_by_state[fiscal_year], 2023 ) / SUMIFS( electric_vehicle_sales_by_state[total_vehicles_sold], electric_vehicle_sales_by_state[state], A9, electric_vehicle_sales_by_state[vehicle_category], "4-Wheelers", electric_vehicle_sales_by_state[fiscal_year], 2023 ), 0) -> 0.0012036328 | R9: =IFERROR( SUMIFS( electric_vehicle_sales_by_state[electric_vehicles_sold], electric_vehicle_sales_by_state[state], A9, electric_vehicle_sales_by_state[vehicle_category], "2-Wheelers", electric_vehicle_sales_by_state[fiscal_year], 2024 ) / SUMIFS( electric_vehicle_sales_by_state[total_vehicles_sold], electric_vehicle_sales_by_state[state], A9, electric_vehicle_sales_by_state[vehicle_category], "2-Wheelers", electric_vehicle_sales_by_state[fiscal_year], 2024 ), 0) -> 0.025112395 | S9: =IFERROR( SUMIFS( electric_vehicle_sales_by_state[electric_vehicles_sold], electric_vehicle_sales_by_state[state], A9, electric_vehicle_sales_by_state[vehicle_category], "4-Wheelers", electric_vehicle_sales_by_state[fiscal_year], 2024 ) / SUMIFS( electric_vehicle_sales_by_state[total_vehicles_sold], electric_vehicle_sales_by_state[state], A9, electric_vehicle_sales_by_state[vehicle_category], "4-Wheelers", electric_vehicle_sales_by_state[fiscal_year], 2024 ), 0) -> 0.0030150024
A10: Ladakh | B10: =SUMIFS(electric_vehicle_sales_by_state[electric_vehicles_sold],electric_vehicle_sales_by_state[state], A10,electric_vehicle_sales_by_state[fiscal_year],2022) -> 12 | C10: =SUMIFS(electric_vehicle_sales_by_state[total_vehicles_sold],electric_vehicle_sales_by_state[state], A10,electric_vehicle_sales_by_state[fiscal_year],2022) -> 2911 | D10: =SUMIFS(electric_vehicle_sales_by_state[electric_vehicles_sold],electric_vehicle_sales_by_state[state], A10,electric_vehicle_sales_by_state[fiscal_year],2023) -> 25 | E10: =SUMIFS(electric_vehicle_sales_by_state[total_vehicles_sold],electric_vehicle_sales_by_state[state], A10,electric_vehicle_sales_by_state[fiscal_year],2023) -> 4379 | F10: =SUMIFS(electric_vehicle_sales_by_state[electric_vehicles_sold],electric_vehicle_sales_by_state[state], A10,electric_vehicle_sales_by_state[fiscal_year],2024) -> 31 | G10: =SUMIFS(electric_vehicle_sales_by_state[total_vehicles_sold],electric_vehicle_sales_by_state[state], A10,electric_vehicle_sales_by_state[fiscal_year],2024) -> 3206 | H10: =IFERROR((B10/C10), 0) -> 0.0041222947 | I10: =IFERROR((D10/E10), 0) -> 0.005709066 | J10: =IFERROR((F10/G10), 0) -> 0.0096693699 | K10: =IFERROR((I10-H10),0) -> 0.0015867713 | L10: =IFERROR((J10-I10),0) -> 0.0039603039 | M10: =IFERROR((Table8[[#This Row],[PR_2024]]-Table8[[#This Row],[PR_2022]]),0) -> 0.0055470752 | N10: =IFERROR( SUMIFS( electric_vehicle_sales_by_state[electric_vehicles_sold], electric_vehicle_sales_by_state[state], A10, electric_vehicle_sales_by_state[vehicle_category], "2-Wheelers", electric_vehicle_sales_by_state[fiscal_year], 2022 ) / SUMIFS( electric_vehicle_sales_by_state[total_vehicles_sold], electric_vehicle_sales_by_state[state], A10, electric_vehicle_sales_by_state[vehicle_category], "2-Wheelers", electric_vehicle_sales_by_state[fiscal_year], 2022 ), 0) -> 0.044776119 | O10: =IFERROR( SUMIFS( electric_vehicle_sales_by_state[electric_vehicles_sold], electric_vehicle_sales_by_state[state], A10, electric_vehicle_sales_by_state[vehicle_category], "4-Wheelers", electric_vehicle_sales_by_state[fiscal_year], 2022 ) / SUMIFS( electric_vehicle_sales_by_state[total_vehicles_sold], electric_vehicle_sales_by_state[state], A10, electric_vehicle_sales_by_state[vehicle_category], "4-Wheelers", electric_vehicle_sales_by_state[fiscal_year], 2022 ), 0) -> 0 | P10: =IFERROR( SUMIFS( electric_vehicle_sales_by_state[electric_vehicles_sold], electric_vehicle_sales_by_state[state], A10, electric_vehicle_sales_by_state[vehicle_category], "2-Wheelers", electric_vehicle_sales_by_state[fiscal_year], 2023 ) / SUMIFS( electric_vehicle_sales_by_state[total_vehicles_sold], electric_vehicle_sales_by_state[state], A10, electric_vehicle_sales_by_state[vehicle_category], "2-Wheelers", electric_vehicle_sales_by_state[fiscal_year], 2023 ), 0) -> 0.0073277968 | Q10: =IFERROR( SUMIFS( electric_vehicle_sales_by_state[electric_vehicles_sold], electric_vehicle_sales_by_state[state], A10, electric_vehicle_sales_by_state[vehicle_category], "4-Wheelers", electric_vehicle_sales_by_state[fiscal_year], 2023 ) / SUMIFS( electric_vehicle_sales_by_state[total_vehicles_sold], electric_vehicle_sales_by_state[state], A10, electric_vehicle_sales_by_state[vehicle_category], "4-Wheelers", electric_vehicle_sales_by_state[fiscal_year], 2023 ), 0) -> 0.0042881647 | R10: =IFERROR( SUMIFS( electric_vehicle_sales_by_state[electric_vehicles_sold], electric_vehicle_sales_by_state[state], A10, electric_vehicle_sales_by_state[vehicle_category], "2-Wheelers", electric_vehicle_sales_by_state[fiscal_year], 2024 ) / SUMIFS( electric_vehicle_sales_by_state[total_vehicles_sold], electric_vehicle_sales_by_state[state], A10, electric_vehicle_sales_by_state[vehicle_category], "2-Wheelers", electric_vehicle_sales_by_state[fiscal_year], 2024 ), 0) -> 0.040629096 | S10: =IFERROR( SUMIFS( electric_vehicle_sales_by_state[electric_vehicles_sold], electric_vehicle_sales_by_state[state], A10, electric_vehicle_sales_by_state[vehicle_category], "4-Wheelers", electric_vehicle_sales_by_state[fiscal_year], 2024 ) / SUMIFS( electric_vehicle_sales_by_state[total_vehicles_sold], electric_vehicle_sales_by_state[state], A10, electric_vehicle_sales_by_state[vehicle_category], "4-Wheelers", electric_vehicle_sales_by_state[fiscal_year], 2024 ), 0) -> 0
A11: Manipur | B11: =SUMIFS(electric_vehicle_sales_by_state[electric_vehicles_sold],electric_vehicle_sales_by_state[state], A11,electric_vehicle_sales_by_state[fiscal_year],2022) -> 25 | C11: =SUMIFS(electric_vehicle_sales_by_state[total_vehicles_sold],electric_vehicle_sales_by_state[state], A11,electric_vehicle_sales_by_state[fiscal_year],2022) -> 36129 | D11: =SUMIFS(electric_vehicle_sales_by_state[electric_vehicles_sold],electric_vehicle_sales_by_state[state], A11,electric_vehicle_sales_by_state[fiscal_year],2023) -> 148 | E11: =SUMIFS(electric_vehicle_sales_by_state[total_vehicles_sold],electric_vehicle_sales_by_state[state], A11,electric_vehicle_sales_by_state[fiscal_year],2023) -> 49962 | F11: =SUMIFS(electric_vehicle_sales_by_state[electric_vehicles_sold],electric_vehicle_sales_by_state[state], A11,electric_vehicle_sales_by_state[fiscal_year],2024) -> 126 | G11: =SUMIFS(electric_vehicle_sales_by_state[total_vehicles_sold],electric_vehicle_sales_by_state[state], A11,electric_vehicle_sales_by_state[fiscal_year],2024) -> 18422 | H11: =IFERROR((B11/C11), 0) -> 0.0006919649 | I11: =IFERROR((D11/E11), 0) -> 0.0029622513 | J11: =IFERROR((F11/G11), 0) -> 0.0068396482 | K11: =IFERROR((I11-H11),0) -> 0.0022702864 | L11: =IFERROR((J11-I11),0) -> 0.0038773969 | M11: =IFERROR((Table8[[#This Row],[PR_2024]]-Table8[[#This Row],[PR_2022]]),0) -> 0.0061476833 | N11: =IFERROR( SUMIFS( electric_vehicle_sales_by_state[electric_vehicles_sold], electric_vehicle_sales_by_state[state], A11, electric_vehicle_sales_by_state[vehicle_category], "2-Wheelers", electric_vehicle_sales_by_state[fiscal_year], 2022 ) / SUMIFS( electric_vehicle_sales_by_state[total_vehicles_sold], electric_vehicle_sales_by_state[state], A11, electric_vehicle_sales_by_state[vehicle_category], "2-Wheelers", electric_vehicle_sales_by_state[fiscal_year], 2022 ), 0) -> 0.00087458457 | O11: =IFERROR( SUMIFS( electric_vehicle_sales_by_state[electric_vehicles_sold], electric_vehicle_sales_by_state[state], A11, electric_vehicle_sales_by_state[vehicle_category], "4-Wheelers", electric_vehicle_sales_by_state[fiscal_year], 2022 ) / SUMIFS( electric_vehicle_sales_by_state[total_vehicles_sold], electric_vehicle_sales_by_state[state], A11, electric_vehicle_sales_by_state[vehicle_category], "4-Wheelers", electric_vehicle_sales_by_state[fiscal_year], 2022 ), 0) -> 0 | P11: =IFERROR( SUMIFS( electric_vehicle_sales_by_state[electric_vehicles_sold], electric_vehicle_sales_by_state[state], A11, electric_vehicle_sales_by_state[vehicle_category], "2-Wheelers", electric_vehicle_sales_by_state[fiscal_year], 2023 ) / SUMIFS( electric_vehicle_sales_by_state[total_vehicles_sold], electric_vehicle_sales_by_state[state], A11, electric_vehicle_sales_by_state[vehicle_category], "2-Wheelers", electric_vehicle_sales_by_state[fiscal_year], 2023 ), 0) -> 0.0035059399 | Q11: =IFERROR( SUMIFS( electric_vehicle_sales_by_state[electric_vehicles_sold], electric_vehicle_sales_by_state[state], A11, electric_vehicle_sales_by_state[vehicle_category], "4-Wheelers", electric_vehicle_sales_by_state[fiscal_year], 2023 ) / SUMIFS( electric_vehicle_sales_by_state[total_vehicles_sold], electric_vehicle_sales_by_state[state], A11, electric_vehicle_sales_by_state[vehicle_category], "4-Wheelers", electric_vehicle_sales_by_state[fiscal_year], 2023 ), 0) -> 0.00087251575 | R11: =IFERROR( SUMIFS( electric_vehicle_sales_by_state[electric_vehicles_sold], electric_vehicle_sales_by_state[state], A11, electric_vehicle_sales_by_state[vehicle_category], "2-Wheelers", electric_vehicle_sales_by_state[fiscal_year], 2024 ) / SUMIFS( electric_vehicle_sales_by_state[total_vehicles_sold], electric_vehicle_sales_by_state[state], A11, electric_vehicle_sales_by_state[vehicle_category], "2-Wheelers", electric_vehicle_sales_by_state[fiscal_year], 2024 ), 0) -> 0.0062059238 | S11: =IFERROR( SUMIFS( electric_vehicle_sales_by_state[electric_vehicles_sold], electric_vehicle_sales_by_state[state], A11, electric_vehicle_sales_by_state[vehicle_category], "4-Wheelers", electric_vehicle_sales_by_state[fiscal_year], 2024 ) / SUMIFS( electric_vehicle_sales_by_state[total_vehicles_sold], electric_vehicle_sales_by_state[state], A11, electric_vehicle_sales_by_state[vehicle_category], "4-Wheelers", electric_vehicle_sales_by_state[fiscal_year], 2024 ), 0) -> 0.0089580387
A12: Meghalaya | B12: =SUMIFS(electric_vehicle_sales_by_state[electric_vehicles_sold],electric_vehicle_sales_by_state[state], A12,electric_vehicle_sales_by_state[fiscal_year],2022) -> 4 | C12: =SUMIFS(electric_vehicle_sales_by_state[total_vehicles_sold],electric_vehicle_sales_by_state[state], A12,electric_vehicle_sales_by_state[fiscal_year],2022) -> 22193 | D12: =SUMIFS(electric_vehicle_sales_by_state[electric_vehicles_sold],electric_vehicle_sales_by_state[state], A12,electric_vehicle_sales_by_state[fiscal_year],2023) -> 40 | E12: =SUMIFS(electric_vehicle_sales_by_state[total_vehicles_sold],electric_vehicle_sales_by_state[state], A12,electric_vehicle_sales_by_state[fiscal_year],2023) -> 31362 | F12: =SUMIFS(electric_vehicle_sales_by_state[electric_vehicles_sold],electric_vehicle_sales_by_state[state], A12,electric_vehicle_sales_by_state[fiscal_year],2024) -> 133 | G12: =SUMIFS(electric_vehicle_sales_by_state[total_vehicles_sold],electric_vehicle_sales_by_state[state], A12,electric_vehicle_sales_by_state[fiscal_year],2024) -> 36628 | H12: =IFERROR((B12/C12), 0) -> 0.00018023701 | I12: =IFERROR((D12/E12), 0) -> 0.0012754289 | J12: =IFERROR((F12/G12), 0) -> 0.0036311019 | K12: =IFERROR((I12-H12),0) -> 0.0010951919 | L12: =IFERROR((J12-I12),0) -> 0.002355673 | M12: =IFERROR((Table8[[#This Row],[PR_2024]]-Table8[[#This Row],[PR_2022]]),0) -> 0.0034508649 | N12: =IFERROR( SUMIFS( electric_vehicle_sales_by_state[electric_vehicles_sold], electric_vehicle_sales_by_state[state], A12, electric_vehicle_sales_by_state[vehicle_category], "2-Wheelers", electric_vehicle_sales_by_state[fiscal_year], 2022 ) / SUMIFS( electric_vehicle_sales_by_state[total_vehicles_sold], electric_vehicle_sales_by_state[state], A12, electric_vehicle_sales_by_state[vehicle_category], "2-Wheelers", electric_vehicle_sales_by_state[fiscal_year], 2022 ), 0) -> 0 | O12: =IFERROR( SUMIFS( electric_vehicle_sales_by_state[electric_vehicles_sold], electric_vehicle_sales_by_state[state], A12, electric_vehicle_sales_by_state[vehicle_category], "4-Wheelers", electric_vehicle_sales_by_state[fiscal_year], 2022 ) / SUMIFS( electric_vehicle_sales_by_state[total_vehicles_sold], electric_vehicle_sales_by_state[state], A12, electric_vehicle_sales_by_state[vehicle_category], "4-Wheelers", electric_vehicle_sales_by_state[fiscal_year], 2022 ), 0) -> 0.00043224552 | P12: =IFERROR( SUMIFS( electric_vehicle_sales_by_state[electric_vehicles_sold], electric_vehicle_sales_by_state[state], A12, electric_vehicle_sales_by_state[vehicle_category], "2-Wheelers", electric_vehicle_sales_by_state[fiscal_year], 2023 ) / SUMIFS( electric_vehicle_sales_by_state[total_vehicles_sold], electric_vehicle_sales_by_state[state], A12, electric_vehicle_sales_by_state[vehicle_category], "2-Wheelers", electric_vehicle_sales_by_state[fiscal_year], 2023 ), 0) -> 0.0016105743 | Q12: =IFERROR( SUMIFS( electric_vehicle_sales_by_state[electric_vehicles_sold], electric_vehicle_sales_by_state[state], A12, electric_vehicle_sales_by_state[vehicle_category], "4-Wheelers", electric_vehicle_sales_by_state[fiscal_year], 2023 ) / SUMIFS( electric_vehicle_sales_by_state[total_vehicles_sold], electric_vehicle_sales_by_state[state], A12, electric_vehicle_sales_by_state[vehicle_category], "4-Wheelers", electric_vehicle_sales_by_state[fiscal_year], 2023 ), 0) -> 0.00082359988 | R12: =IFERROR( SUMIFS( electric_vehicle_sales_by_state[electric_vehicles_sold], electric_vehicle_sales_by_state[state], A12, electric_vehicle_sales_by_state[vehicle_category], "2-Wheelers", electric_vehicle_sales_by_state[fiscal_year], 2024 ) / SUMIFS( electric_vehicle_sales_by_state[total_vehicles_sold], electric_vehicle_sales_by_state[state], A12, electric_vehicle_sales_by_state[vehicle_category], "2-Wheelers", electric_vehicle_sales_by_state[fiscal_year], 2024 ), 0) -> 0.004714883 | S12: =IFERROR( SUMIFS( electric_vehicle_sales_by_state[electric_vehicles_sold], electric_vehicle_sales_by_state[state], A12, electric_vehicle_sales_by_state[vehicle_category], "4-Wheelers", electric_vehicle_sales_by_state[fiscal_year], 2024 ) / SUMIFS( electric_vehicle_sales_by_state[total_vehicles_sold], electric_vehicle_sales_by_state[state], A12, electric_vehicle_sales_by_state[vehicle_category], "4-Wheelers", electric_vehicle_sales_by_state[fiscal_year], 2024 ), 0) -> 0.0019086668
A13: Mizoram | B13: =SUMIFS(electric_vehicle_sales_by_state[electric_vehicles_sold],electric_vehicle_sales_by_state[state], A13,electric_vehicle_sales_by_state[fiscal_year],2022) -> 0 | C13: =SUMIFS(electric_vehicle_sales_by_state[total_vehicles_sold],electric_vehicle_sales_by_state[state], A13,electric_vehicle_sales_by_state[fiscal_year],2022) -> 19439 | D13: =SUMIFS(electric_vehicle_sales_by_state[electric_vehicles_sold],electric_vehicle_sales_by_state[state], A13,electric_vehicle_sales_by_state[fiscal_year],2023) -> 65 | E13: =SUMIFS(electric_vehicle_sales_by_state[total_vehicles_sold],electric_vehicle_sales_by_state[state], A13,electric_vehicle_sales_by_state[fiscal_year],2023) -> 24446 | F13: =SUMIFS(electric_vehicle_sales_by_state[electric_vehicles_sold],electric_vehicle_sales_by_state[state], A13,electric_vehicle_sales_by_state[fiscal_year],2024) -> 275 | G13: =SUMIFS(electric_vehicle_sales_by_state[total_vehicles_sold],electric_vehicle_sales_by_state[state], A13,electric_vehicle_sales_by_state[fiscal_year],2024) -> 27422 | H13: =IFERROR((B13/C13), 0) -> 0 | I13: =IFERROR((D13/E13), 0) -> 0.0026589217 | J13: =IFERROR((F13/G13), 0) -> 0.010028444 | K13: =IFERROR((I13-H13),0) -> 0.0026589217 | L13: =IFERROR((J13-I13),0) -> 0.0073695226 | M13: =IFERROR((Table8[[#This Row],[PR_2024]]-Table8[[#This Row],[PR_2022]]),0) -> 0.010028444 | N13: =IFERROR( SUMIFS( electric_vehicle_sales_by_state[electric_vehicles_sold], electric_vehicle_sales_by_state[state], A13, electric_vehicle_sales_by_state[vehicle_category], "2-Wheelers", electric_vehicle_sales_by_state[fiscal_year], 2022 ) / SUMIFS( electric_vehicle_sales_by_state[total_vehicles_sold], electric_vehicle_sales_by_state[state], A13, electric_vehicle_sales_by_state[vehicle_category], "2-Wheelers", electric_vehicle_sales_by_state[fiscal_year], 2022 ), 0) -> 0 | O13: =IFERROR( SUMIFS( electric_vehicle_sales_by_state[electric_vehicles_sold], electric_vehicle_sales_by_state[state], A13, electric_vehicle_sales_by_state[vehicle_category], "4-Wheelers", electric_vehicle_sales_by_state[fiscal_year], 2022 ) / SUMIFS( electric_vehicle_sales_by_state[total_vehicles_sold], electric_vehicle_sales_by_state[state], A13, electric_vehicle_sales_by_state[vehicle_category], "4-Wheelers", electric_vehicle_sales_by_state[fiscal_year], 2022 ), 0) -> 0 | P13: =IFERROR( SUMIFS( electric_vehicle_sales_by_state[electric_vehicles_sold], electric_vehicle_sales_by_state[state], A13, electric_vehicle_sales_by_state[vehicle_category], "2-Wheelers", electric_vehicle_sales_by_state[fiscal_year], 2023 ) / SUMIFS( electric_vehicle_sales_by_state[total_vehicles_sold], electric_vehicle_sales_by_state[state], A13, electric_vehicle_sales_by_state[vehicle_category], "2-Wheelers", electric_vehicle_sales_by_state[fiscal_year], 2023 ), 0) -> 0.0032801776 | Q13: =IFERROR( SUMIFS( electric_vehicle_sales_by_state[electric_vehicles_sold], electric_vehicle_sales_by_state[state], A13, electric_vehicle_sales_by_state[vehicle_category], "4-Wheelers", electric_vehicle_sales_by_state[fiscal_year], 2023 ) / SUMIFS( electric_vehicle_sales_by_state[total_vehicles_sold], electric_vehicle_sales_by_state[state], A13, electric_vehicle_sales_by_state[vehicle_category], "4-Wheelers", electric_vehicle_sales_by_state[fiscal_year], 2023 ), 0) -> 0 | R13: =IFERROR( SUMIFS( electric_vehicle_sales_by_state[electric_vehicles_sold], electric_vehicle_sales_by_state[state], A13, electric_vehicle_sales_by_state[vehicle_category], "2-Wheelers", electric_vehicle_sales_by_state[fiscal_year], 2024 ) / SUMIFS( electric_vehicle_sales_by_state[total_vehicles_sold], electric_vehicle_sales_by_state[state], A13, electric_vehicle_sales_by_state[vehicle_category], "2-Wheelers", electric_vehicle_sales_by_state[fiscal_year], 2024 ), 0) -> 0.012434763 | S13: =IFERROR( SUMIFS( electric_vehicle_sales_by_state[electric_vehicles_sold], electric_vehicle_sales_by_state[state], A13, electric_vehicle_sales_by_state[vehicle_category], "4-Wheelers", electric_vehicle_sales_by_state[fiscal_year], 2024 ) / SUMIFS( electric_vehicle_sales_by_state[total_vehicles_sold], electric_vehicle_sales_by_state[state], A13, electric_vehicle_sales_by_state[vehicle_category], "4-Wheelers", electric_vehicle_sales_by_state[fiscal_year], 2024 ), 0) -> 0.00018563208
